Workbook
Name _1_Modulo: [1]Tablas!$AC$1:$AD$10
Name _2_Modulos: [1]Tablas!$AF$1:$AH$6
Name _2_NIVELES: [2]Hoja1!$F$3:$F$6
Name _2_NIVELES: [2]Hoja1!$F$3:$F$6
Name _2_NIVELES: [2]Hoja1!$F$3:$F$6
Name _2_NIVELES: [2]Hoja1!$F$3:$F$6
Name _3_Modulos: [1]Tablas!$AJ$1:$AL$5
Name _3_NIVELES: [2]Hoja1!$H$3:$H$5
Name _3_NIVELES: [2]Hoja1!$H$3:$H$5
Name _3_NIVELES: [2]Hoja1!$H$3:$H$5
Name _3_NIVELES: [2]Hoja1!$H$3:$H$5
Name _4_Modulos: [1]Tablas!$AN$1:$AP$4
Name CuotaInicial: [1]!Tabla7[#All]
Name Descuentos: [1]!Tabla6[#All]
Name Descuentos_Especiales: [1]!Tabla3[#All]
Name NIVELES: [2]Hoja1!$B$4:$B$7
Name NIVELES: [2]Hoja1!$B$4:$B$7
Name NIVELES: [2]Hoja1!$B$4:$B$7
Name NIVELES: [2]Hoja1!$B$4:$B$7
Name Plazos: [1]!Tabla5[#All]
Name Precios_plenos: [1]Tablas!$A$1:$D$7
Name UN_NIVEL: [2]Hoja1!$D$4:$D$7
Name UN_NIVEL: [2]Hoja1!$D$4:$D$7
Name UN_NIVEL: [2]Hoja1!$D$4:$D$7
Name UN_NIVEL: [2]Hoja1!$D$4:$D$7
Name _2_NIVELES: #REF!
Name DASDASDASD: #REF!
Name FDSFSDF: #REF!
Name _3_NIVELES: #REF!
Name _2_NIVELES: #REF!
Name SADASDAD: #REF!
Name SADASDAD: #REF!
Name ASDASDA: #REF!
Name _3_NIVELES: #REF!
Name NIVELES: #REF!
Name ASDASDA: #REF!
Name DSDS: #REF!
Name UN_NIVEL: #REF!
Name NIVELES: #REF!
Name ASDASDA: #REF!
Name FDSFSDF: #REF!
Name _3333: #REF!
Name DASDASDASD: #REF!
Name SADASDAD: #REF!
Name DASDASDASD: #REF!
Name UN_NIVEL: #REF!
Name FDSFSDF: #REF!

Sheet Incre IPC 2025
A1: IPC 2025 | B1: 0.05
B2: 2025 | C2: 2026 | D2: INCREMENTO IPC 2026 | E2: 2026 FINAL | F2: % INCREMENTO | G2: $ INCREMENTO
A3: 6 Meses | B3: 2104000 | C3: =+B3+(B3*$D$3) -> 2209200 | D3: 0.05 | E3: =CEILING(C3,1000) -> 2210000 | F3: =+(E3-B3)/B3 -> 0.050380228 | G3: =+E3-B3 -> 106000
A4: 9 Meses | B4: 3156000 | C4: =+B4+(B4*$D$3) -> 3313800 | E4: =CEILING(C4,1000) -> 3314000 | F4: =+(E4-B4)/B4 -> 0.050063371 | G4: =+E4-B4 -> 158000
A5: 12 Meses | B5: 4208000 | C5: =+B5+(B5*$D$3) -> 4418400 | E5: =CEILING(C5,1000) -> 4419000 | F5: =+(E5-B5)/B5 -> 0.050142586 | G5: =+E5-B5 -> 211000
A7: Preparcion 2H | B7: 357700 | C7: =+B7+(B7*$D$7) -> 375585 | D7: 0.05 | E7: =CEILING(C7,100) -> 375600 | F7: =+(E7-B7)/B7 -> 0.050041935 | G7: =+E7-B7 -> 17900
A8: Preparcion 4H | B8: 549200 | C8: =+B8+(B8*$D$7) -> 576660 | E8: =CEILING(C8,100) -> 576700 | F8: =+(E8-B8)/B8 -> 0.050072833 | G8: =+E8-B8 -> 27500
A9: Smart Chef | B9: 549200 | C9: =+B9+(B9*$D$7) -> 576660 | E9: =CEILING(C9,100) -> 576700 | F9: =+(E9-B9)/B9 -> 0.050072833 | G9: =+E9-B9 -> 27500
A10: Smart Office Suite Skills | B10: 755400 | C10: =+B10+(B10*$D$7) -> 793170 | E10: =CEILING(C10,100) -> 793200 | F10: =+(E10-B10)/B10 -> 0.050039714 | G10: =+E10-B10 -> 37800
A11: Smart Bussines English | B11: 823800 | C11: =+B11+(B11*$D$7) -> 864990 | E11: =CEILING(C11,100) -> 865000 | F11: =+(E11-B11)/B11 -> 0.050012139 | G11: =+E11-B11 -> 41200

Sheet Resumen Inst
D1: TARIFA PUBLICO | G1: TARIFA ALIANZA | J1: TARIFA PREVENTA | M1: TARIFA COLABORADOR
B2: NIVELES | C2: PRECIO 2024 | D2: PRECIO CONTADO | E2: PRECIO FINAN CORTO (2, 3, 4 Y 5 CUOTAS) | F2: PRECIO FINAN FULL | G2: PRECIO CONTADO | H2: PRECIO FINAN CORTO (2, 3, 4 Y 5 CUOTAS) | I2: PRECIO FINAN FULL | J2: PRECIO CONTADO | K2: PRECIO FINAN CORTO (2, 3, 4 Y 5 CUOTAS) | L2: PRECIO FINAN FULL | M2: PRECIO CONTADO | N2: PRECIO FINAN CORTO (2, 3, 4 Y 5 CUOTAS) | O2: PRECIO FINAN FULL
B3: 6 meses | C3: 2000000 | D3: =C3*0.75 -> 1500000 | E3: N/A | F3: =C3*0.95 -> 1900000 | G3: =D3*0.9 -> 1350000 | H3: N/A | I3: =F3*0.9 -> 1710000 | J3: =D3*0.85 -> 1275000 | K3: N/A | L3: =F3*0.85 -> 1615000 | M3: =D3*0.8 -> 1200000 | N3: N/A | O3: =F3*0.8 -> 1520000
B4: 9 meses | C4: 3000000 | D4: =C4*0.6 -> 1800000 | E4: =C4*0.65 -> 1950000 | F4: =C4*0.85 -> 2550000 | G4: =D4*0.9 -> 1620000 | H4: =E4*0.9 -> 1755000 | I4: =F4*0.9 -> 2295000 | J4: =D4*0.85 -> 1530000 | K4: =E4*0.85 -> 1657500 | L4: =F4*0.85 -> 2167500 | M4: =D4*0.8 -> 1440000 | N4: =E4*0.8 -> 1560000 | O4: =F4*0.8 -> 2040000
B5: 12 meses | C5: 4000000 | D5: =C5*0.5 -> 2000000 | E5: =C5*0.55 -> 2200000 | F5: =C5*0.8 -> 3200000 | G5: =D5*0.9 -> 1800000 | H5: =E5*0.9 -> 1980000 | I5: =F5*0.9 -> 2880000 | J5: =D5*0.85 -> 1700000 | K5: =E5*0.85 -> 1870000 | L5: =F5*0.85 -> 2720000 | M5: =D5*0.8 -> 1600000 | N5: =E5*0.8 -> 1760000 | O5: =F5*0.8 -> 2560000

Sheet Tarifas Instituto 2024
C1: 0.03
C3: TARIFAS INGLES / FRANCES INSTITUTO 2024 PRECIO AL PUBLICO | N3: TARIFAS INGLES / FRANCES INSTITUTO 2024 PRECIO CONVENIO EMPRESARIAL / CAMPAÑA 10% ADICIONAL | Y3: TARIFAS INGLES / FRANCES INSTITUTO 2024 PRECIO CAMPAÑA PREVENTA / ESPECIAL 15% ADICIONAL | AJ3: TARIFAS INGLES / FRANCES INSTITUTO 2024 PRECIO COLABORADOR / 20% ADICIONAL
C6: Plan 1 Nivel (162 Horas Académicas Niveles A1 o A2) | N6: Plan 1 Nivel (162 Horas Académicas Niveles A1 o A2) | Y6: Plan 1 Nivel (162 Horas Académicas Niveles A1 o A2) | AJ6: Plan 1 Nivel (162 Horas Académicas Niveles A1 o A2)
C7: VALOR FULL PLAN | D7: N° CUOTAS | E7: DESCUENTO | F7: CUOTA INICIAL | G7: VALOR CUOTAS | H7: VALOR TOTAL | I7: VALOR HORA | J7: MAXIMA INTENSIDAD MENSUAL | N7: VALOR FULL PLAN | O7: N° CUOTAS | P7: DESCUENTO | Q7: CUOTA INICIAL | R7: VALOR CUOTAS | S7: VALOR TOTAL | T7: VALOR HORA | U7: MAXIMA INTENSIDAD MENSUAL | Y7: VALOR FULL PLAN | Z7: N° CUOTAS | AA7: DESCUENTO | AB7: CUOTA INICIAL | AC7: VALOR CUOTAS | AD7: VALOR TOTAL | AE7: VALOR HORA | AF7: MAXIMA INTENSIDAD MENSUAL | AJ7: VALOR FULL PLAN | AK7: N° CUOTAS | AL7: DESCUENTO | AM7: CUOTA INICIAL | AN7: VALOR CUOTAS | AO7: VALOR TOTAL | AP7: VALOR HORA | AQ7: MAXIMA INTENSIDAD MENSUAL
C8: =+'Incre IPC 2025'!#REF! -> #ERROR! | D8: 1 | E8: 0.15 | F8: =H8 -> #ERROR! | G8: 0 | H8: =C8-(C8*E8) -> #ERROR! | I8: =H8/J$8 -> #ERROR! | J8: 162 | N8: =+C8 -> #ERROR! | O8: 1 | P8: =(N8-S8)/N8 -> #ERROR! | Q8: =S8 -> #ERROR! | R8: 0 | S8: =H8*0.9 -> #ERROR! | T8: =S8/U8 -> #ERROR! | U8: 162 | Y8: =+C8 -> #ERROR! | Z8: 1 | AA8: =(Y8-AD8)/Y8 -> #ERROR! | AB8: =AD8 -> #ERROR! | AC8: 0 | AD8: =H8*0.85 -> #ERROR! | AE8: =AD8/AF8 -> #ERROR! | AF8: 162 | AJ8: =+C8 -> #ERROR! | AK8: 1 | AL8: =(AJ8-AO8)/AJ8 -> #ERROR! | AM8: =AO8 -> #ERROR! | AN8: 0 | AO8: =H8*0.8 -> #ERROR! | AP8: =AO8/AQ8 -> #ERROR! | AQ8: 162
D9: 6 | E9: 0 | F9: =H9/D9 -> #ERROR! | G9: =(H9-F9)/(D9-1) -> #ERROR! | H9: =C8-(C8*E9) -> #ERROR! | I9: =H9/J8 -> #ERROR! | J9: =J8/D9 -> 27 | O9: =+D9 -> 6 | P9: =(N8-S9)/N8 -> #ERROR! | Q9: =F9-(F9*10%) -> #ERROR! | R9: =(S9-Q9)/(O9-1) -> #ERROR! | S9: =H9*0.9 -> #ERROR! | T9: =S9/U8 -> #ERROR! | U9: =U8/O9 -> 27 | Z9: =+D9 -> 6 | AA9: =(Y8-AD9)/Y8 -> #ERROR! | AB9: =F9-(F9*15%) -> #ERROR! | AC9: =(AD9-AB9)/(Z9-1) -> #ERROR! | AD9: =H9*0.85 -> #ERROR! | AE9: =AD9/AF8 -> #ERROR! | AF9: =AF8/Z9 -> 27 | AK9: =+D9 -> 6 | AL9: =(AJ8-AO9)/AJ8 -> #ERROR! | AM9: =F9-(F9*20%) -> #ERROR! | AN9: =(AO9-AM9)/(AK9-1) -> #ERROR! | AO9: =H9*0.8 -> #ERROR! | AP9: =AO9/AQ8 -> #ERROR! | AQ9: =AQ8/AK9 -> 27
C11: Plan 1 Nivel (178 Horas Académicas Nivel B1) | N11: Plan 1 Nivel (178 Horas Académicas Nivel B1) | Y11: Plan 1 Nivel (178 Horas Académicas Nivel B1) | AJ11: Plan 1 Nivel (178 Horas Académicas Nivel B1)
C12: VALOR FULL PLAN | D12: N° CUOTAS | E12: DESCUENTO | F12: CUOTA INICIAL | G12: VALOR CUOTAS | H12: VALOR TOTAL | I12: VALOR HORA | J12: MAXIMA INTENSIDAD MENSUAL | N12: VALOR FULL PLAN | O12: N° CUOTAS | P12: DESCUENTO | Q12: CUOTA INICIAL | R12: VALOR CUOTAS | S12: VALOR TOTAL | T12: VALOR HORA | U12: MAXIMA INTENSIDAD MENSUAL | Y12: VALOR FULL PLAN | Z12: N° CUOTAS | AA12: DESCUENTO | AB12: CUOTA INICIAL | AC12: VALOR CUOTAS | AD12: VALOR TOTAL | AE12: VALOR HORA | AF12: MAXIMA INTENSIDAD MENSUAL | AJ12: VALOR FULL PLAN | AK12: N° CUOTAS | AL12: DESCUENTO | AM12: CUOTA INICIAL | AN12: VALOR CUOTAS | AO12: VALOR TOTAL | AP12: VALOR HORA | AQ12: MAXIMA INTENSIDAD MENSUAL
C13: =+'Incre IPC 2025'!#REF! -> #ERROR! | D13: 1 | E13: 0.15 | F13: =H13 -> #ERROR! | G13: 0 | H13: =C13-(C13*E13) -> #ERROR! | I13: =H13/J13 -> #ERROR! | J13: 178 | N13: =+C13 -> #ERROR! | O13: 1 | P13: =(N13-S13)/N13 -> #ERROR! | Q13: =S13 -> #ERROR! | R13: 0 | S13: =H13*0.9 -> #ERROR! | T13: =S13/U13 -> #ERROR! | U13: 178 | Y13: =+C13 -> #ERROR! | Z13: 1 | AA13: =(Y13-AD13)/Y13 -> #ERROR! | AB13: =AD13 -> #ERROR! | AC13: 0 | AD13: =H13*0.85 -> #ERROR! | AE13: =AD13/AF13 -> #ERROR! | AF13: 178 | AJ13: =+C13 -> #ERROR! | AK13: 1 | AL13: =(AJ13-AO13)/AJ13 -> #ERROR! | AM13: =AO13 -> #ERROR! | AN13: 0 | AO13: =H13*0.8 -> #ERROR! | AP13: =AO13/AQ13 -> #ERROR! | AQ13: 178
D14: 6 | E14: 0 | F14: =H14/D14 -> #ERROR! | G14: =(H14-F14)/(D14-1) -> #ERROR! | H14: =C13-(C13*E14) -> #ERROR! | I14: =H14/J13 -> #ERROR! | J14: =J13/D14 -> 29.666667 | O14: =+D14 -> 6 | P14: =(N13-S14)/N13 -> #ERROR! | Q14: =F14-(F14*10%) -> #ERROR! | R14: =(S14-Q14)/(O14-1) -> #ERROR! | S14: =H14*0.9 -> #ERROR! | T14: =S14/U13 -> #ERROR! | U14: =U13/O14 -> 29.666667 | Z14: =+D14 -> 6 | AA14: =(Y13-AD14)/Y13 -> #ERROR! | AB14: =F14-(F14*15%) -> #ERROR! | AC14: =(AD14-AB14)/(Z14-1) -> #ERROR! | AD14: =H14*0.85 -> #ERROR! | AE14: =AD14/AF13 -> #ERROR! | AF14: =AF13/Z14 -> 29.666667 | AK14: =+D14 -> 6 | AL14: =(AJ13-AO14)/AJ13 -> #ERROR! | AM14: =F14-(F14*20%) -> #ERROR! | AN14: =(AO14-AM14)/(AK14-1) -> #ERROR! | AO14: =H14*0.8 -> #ERROR! | AP14: =AO14/AQ13 -> #ERROR! | AQ14: =AQ13/AK14 -> 29.666667
C16: Plan 1 Nivel (202 Horas Académicas Niveles B2 o C1) | N16: Plan 1 Nivel (202 Horas Académicas Niveles B2 o C1) | Y16: Plan 1 Nivel (202 Horas Académicas Niveles B2 o C1) | AJ16: Plan 1 Nivel (202 Horas Académicas Niveles B2 o C1)
C17: VALOR FULL PLAN | D17: N° CUOTAS | E17: DESCUENTO | F17: CUOTA INICIAL | G17: VALOR CUOTAS | H17: VALOR TOTAL | I17: VALOR HORA | J17: MAXIMA INTENSIDAD MENSUAL | N17: VALOR FULL PLAN | O17: N° CUOTAS | P17: DESCUENTO | Q17: CUOTA INICIAL | R17: VALOR CUOTAS | S17: VALOR TOTAL | T17: VALOR HORA | U17: MAXIMA INTENSIDAD MENSUAL | Y17: VALOR FULL PLAN | Z17: N° CUOTAS | AA17: DESCUENTO | AB17: CUOTA INICIAL | AC17: VALOR CUOTAS | AD17: VALOR TOTAL | AE17: VALOR HORA | AF17: MAXIMA INTENSIDAD MENSUAL | AJ17: VALOR FULL PLAN | AK17: N° CUOTAS | AL17: DESCUENTO | AM17: CUOTA INICIAL | AN17: VALOR CUOTAS | AO17: VALOR TOTAL | AP17: VALOR HORA | AQ17: MAXIMA INTENSIDAD MENSUAL
C18: =+'Incre IPC 2025'!#REF! -> #ERROR! | D18: 1 | E18: 0.15 | F18: =H18 -> #ERROR! | G18: 0 | H18: =C18-(C18*E18) -> #ERROR! | I18: =H18/J18 -> #ERROR! | J18: 202 | N18: =+C18 -> #ERROR! | O18: 1 | P18: =(N18-S18)/N18 -> #ERROR! | Q18: =S18 -> #ERROR! | R18: 0 | S18: =H18*0.9 -> #ERROR! | T18: =S18/U18 -> #ERROR! | U18: 202 | Y18: =+C18 -> #ERROR! | Z18: 1 | AA18: =(Y18-AD18)/Y18 -> #ERROR! | AB18: =AD18 -> #ERROR! | AC18: 0 | AD18: =H18*0.85 -> #ERROR! | AE18: =AD18/AF18 -> #ERROR! | AF18: 202 | AJ18: =+C18 -> #ERROR! | AK18: 1 | AL18: =(AJ18-AO18)/AJ18 -> #ERROR! | AM18: =AO18 -> #ERROR! | AN18: 0 | AO18: =H18*0.8 -> #ERROR! | AP18: =AO18/AQ18 -> #ERROR! | AQ18: 202
D19: 6 | E19: 0 | F19: =H19/D19 -> #ERROR! | G19: =(H19-F19)/(D19-1) -> #ERROR! | H19: =C18-(C18*E19) -> #ERROR! | I19: =H19/J18 -> #ERROR! | J19: =J18/D19 -> 33.666667 | O19: =+D19 -> 6 | P19: =(N18-S19)/N18 -> #ERROR! | Q19: =F19-(F19*10%) -> #ERROR! | R19: =(S19-Q19)/(O19-1) -> #ERROR! | S19: =H19*0.9 -> #ERROR! | T19: =S19/U18 -> #ERROR! | U19: =U18/O19 -> 33.666667 | Z19: =+D19 -> 6 | AA19: =(Y18-AD19)/Y18 -> #ERROR! | AB19: =F19-(F19*15%) -> #ERROR! | AC19: =(AD19-AB19)/(Z19-1) -> #ERROR! | AD19: =H19*0.85 -> #ERROR! | AE19: =AD19/AF18 -> #ERROR! | AF19: =AF18/Z19 -> 33.666667 | AK19: =+D19 -> 6 | AL19: =(AJ18-AO19)/AJ18 -> #ERROR! | AM19: =F19-(F19*20%) -> #ERROR! | AN19: =(AO19-AM19)/(AK19-1) -> #ERROR! | AO19: =H19*0.8 -> #ERROR! | AP19: =AO19/AQ18 -> #ERROR! | AQ19: =AQ18/AK19 -> 33.666667
C22: Plan 2 Niveles (324 Horas Académicas Niveles A1 y A2) | N22: Plan 2 Niveles (324 Horas Académicas Niveles A1 y A2) | Y22: Plan 2 Niveles (324 Horas Académicas Niveles A1 y A2) | AJ22: Plan 2 Niveles (324 Horas Académicas Niveles A1 y A2)
C23: VALOR FULL PLAN | D23: N° CUOTAS | E23: DESCUENTO | F23: CUOTA INICIAL | G23: VALOR CUOTAS | H23: VALOR TOTAL | I23: VALOR HORA | J23: MAXIMA INTENSIDAD MENSUAL | N23: VALOR FULL PLAN | O23: N° CUOTAS | P23: DESCUENTO | Q23: CUOTA INICIAL | R23: VALOR CUOTAS | S23: VALOR TOTAL | T23: VALOR HORA | U23: MAXIMA INTENSIDAD MENSUAL | Y23: VALOR FULL PLAN | Z23: N° CUOTAS | AA23: DESCUENTO | AB23: CUOTA INICIAL | AC23: VALOR CUOTAS | AD23: VALOR TOTAL | AE23: VALOR HORA | AF23: MAXIMA INTENSIDAD MENSUAL | AJ23: VALOR FULL PLAN | AK23: N° CUOTAS | AL23: DESCUENTO | AM23: CUOTA INICIAL | AN23: VALOR CUOTAS | AO23: VALOR TOTAL | AP23: VALOR HORA | AQ23: MAXIMA INTENSIDAD MENSUAL
C24: =SUM(C8+C8) -> #ERROR! | D24: 1 | E24: 0.3 | F24: =H24 -> #ERROR! | G24: 0 | H24: =C24-(C24*E24) -> #ERROR! | I24: =H24/J24 -> #ERROR! | J24: 324 | N24: =SUM(N8+N8) -> #ERROR! | O24: 1 | P24: =(N24-S24)/N24 -> #ERROR! | Q24: =S24 -> #ERROR! | R24: 0 | S24: =H24*0.9 -> #ERROR! | T24: =S24/U24 -> #ERROR! | U24: 324 | Y24: =SUM(Y8+Y8) -> #ERROR! | Z24: 1 | AA24: =(Y24-AD24)/Y24 -> #ERROR! | AB24: =AD24 -> #ERROR! | AC24: 0 | AD24: =H24*0.85 -> #ERROR! | AE24: =AD24/AF24 -> #ERROR! | AF24: 324 | AJ24: =SUM(AJ8+AJ8) -> #ERROR! | AK24: 1 | AL24: =(AJ24-AO24)/AJ24 -> #ERROR! | AM24: =AO24 -> #ERROR! | AN24: 0 | AO24: =H24*0.8 -> #ERROR! | AP24: =AO24/AQ24 -> #ERROR! | AQ24: 324
D25: 12 | E25: 0.05 | F25: =H25/D25 -> #ERROR! | G25: =(H25-F25)/(D25-1) -> #ERROR! | H25: =C24-(C24*E25) -> #ERROR! | I25: =H25/J24 -> #ERROR! | J25: =J24/D25 -> 27 | O25: =+D25 -> 12 | P25: =(N24-S25)/N24 -> #ERROR! | Q25: =F25-(F25*10%) -> #ERROR! | R25: =(S25-Q25)/(O25-1) -> #ERROR! | S25: =H25*0.9 -> #ERROR! | T25: =S25/U24 -> #ERROR! | U25: =U24/O25 -> 27 | Z25: =+D25 -> 12 | AA25: =(Y24-AD25)/Y24 -> #ERROR! | AB25: =F25-(F25*15%) -> #ERROR! | AC25: =(AD25-AB25)/(Z25-1) -> #ERROR! | AD25: =H25*0.85 -> #ERROR! | AE25: =AD25/AF24 -> #ERROR! | AF25: =AF24/Z25 -> 27 | AK25: =+D25 -> 12 | AL25: =(AJ24-AO25)/AJ24 -> #ERROR! | AM25: =F25-(F25*20%) -> #ERROR! | AN25: =(AO25-AM25)/(AK25-1) -> #ERROR! | AO25: =H25*0.8 -> #ERROR! | AP25: =AO25/AQ24 -> #ERROR! | AQ25: =AQ24/AK25 -> 27
C27: Plan 2 Niveles (340 Horas Académicas Niveles A2 y B1) | N27: Plan 2 Niveles (340 Horas Académicas Niveles A2 y B1) | Y27: Plan 2 Niveles (340 Horas Académicas Niveles A2 y B1) | AJ27: Plan 2 Niveles (340 Horas Académicas Niveles A2 y B1)
C28: VALOR FULL PLAN | D28: N° CUOTAS | E28: DESCUENTO | F28: CUOTA INICIAL | G28: VALOR CUOTAS | H28: VALOR TOTAL | I28: VALOR HORA | J28: MAXIMA INTENSIDAD MENSUAL | N28: VALOR FULL PLAN | O28: N° CUOTAS | P28: DESCUENTO | Q28: CUOTA INICIAL | R28: VALOR CUOTAS | S28: VALOR TOTAL | T28: VALOR HORA | U28: MAXIMA INTENSIDAD MENSUAL | Y28: VALOR FULL PLAN | Z28: N° CUOTAS | AA28: DESCUENTO | AB28: CUOTA INICIAL | AC28: VALOR CUOTAS | AD28: VALOR TOTAL | AE28: VALOR HORA | AF28: MAXIMA INTENSIDAD MENSUAL | AJ28: VALOR FULL PLAN | AK28: N° CUOTAS | AL28: DESCUENTO | AM28: CUOTA INICIAL | AN28: VALOR CUOTAS | AO28: VALOR TOTAL | AP28: VALOR HORA | AQ28: MAXIMA INTENSIDAD MENSUAL
C29: =SUM(C8+C13) -> #ERROR! | D29: 1 | E29: 0.3 | F29: =H29 -> #ERROR! | G29: 0 | H29: =C29-(C29*E29) -> #ERROR! | I29: =H29/J29 -> #ERROR! | J29: 340 | N29: =SUM(N8+N13) -> #ERROR! | O29: 1 | P29: =(N29-S29)/N29 -> #ERROR! | Q29: =S29 -> #ERROR! | R29: 0 | S29: =H29*0.9 -> #ERROR! | T29: =S29/U29 -> #ERROR! | U29: 340 | Y29: =SUM(Y8+Y13) -> #ERROR! | Z29: 1 | AA29: =(Y29-AD29)/Y29 -> #ERROR! | AB29: =AD29 -> #ERROR! | AC29: 0 | AD29: =H29*0.85 -> #ERROR! | AE29: =AD29/AF29 -> #ERROR! | AF29: 340 | AJ29: =SUM(AJ8+AJ13) -> #ERROR! | AK29: 1 | AL29: =(AJ29-AO29)/AJ29 -> #ERROR! | AM29: =AO29 -> #ERROR! | AN29: 0 | AO29: =H29*0.8 -> #ERROR! | AP29: =AO29/AQ29 -> #ERROR! | AQ29: 340
D30: 12 | E30: 0.05 | F30: =H30/D30 -> #ERROR! | G30: =(H30-F30)/(D30-1) -> #ERROR! | H30: =C29-(C29*E30) -> #ERROR! | I30: =H30/J29 -> #ERROR! | J30: =J29/D30 -> 28.333333 | O30: =+D30 -> 12 | P30: =(N29-S30)/N29 -> #ERROR! | Q30: =F30-(F30*10%) -> #ERROR! | R30: =(S30-Q30)/(O30-1) -> #ERROR! | S30: =H30*0.9 -> #ERROR! | T30: =S30/U29 -> #ERROR! | U30: =U29/O30 -> 28.333333 | Z30: =+D30 -> 12 | AA30: =(Y29-AD30)/Y29 -> #ERROR! | AB30: =F30-(F30*15%) -> #ERROR! | AC30: =(AD30-AB30)/(Z30-1) -> #ERROR! | AD30: =H30*0.85 -> #ERROR! | AE30: =AD30/AF29 -> #ERROR! | AF30: =AF29/Z30 -> 28.333333 | AK30: =+D30 -> 12 | AL30: =(AJ29-AO30)/AJ29 -> #ERROR! | AM30: =F30-(F30*20%) -> #ERROR! | AN30: =(AO30-AM30)/(AK30-1) -> #ERROR! | AO30: =H30*0.8 -> #ERROR! | AP30: =AO30/AQ29 -> #ERROR! | AQ30: =AQ29/AK30 -> 28.333333
C32: Plan 2 Niveles (380 Horas Académicas Niveles B1 y B2) | N32: Plan 2 Niveles (380 Horas Académicas Niveles B1 y B2) | Y32: Plan 2 Niveles (380 Horas Académicas Niveles B1 y B2) | AJ32: Plan 2 Niveles (380 Horas Académicas Niveles B1 y B2)
C33: VALOR FULL PLAN | D33: N° CUOTAS | E33: DESCUENTO | F33: CUOTA INICIAL | G33: VALOR CUOTAS | H33: VALOR TOTAL | I33: VALOR HORA | J33: MAXIMA INTENSIDAD MENSUAL | N33: VALOR FULL PLAN | O33: N° CUOTAS | P33: DESCUENTO | Q33: CUOTA INICIAL | R33: VALOR CUOTAS | S33: VALOR TOTAL | T33: VALOR HORA | U33: MAXIMA INTENSIDAD MENSUAL | Y33: VALOR FULL PLAN | Z33: N° CUOTAS | AA33: DESCUENTO | AB33: CUOTA INICIAL | AC33: VALOR CUOTAS | AD33: VALOR TOTAL | AE33: VALOR HORA | AF33: MAXIMA INTENSIDAD MENSUAL | AJ33: VALOR FULL PLAN | AK33: N° CUOTAS | AL33: DESCUENTO | AM33: CUOTA INICIAL | AN33: VALOR CUOTAS | AO33: VALOR TOTAL | AP33: VALOR HORA | AQ33: MAXIMA INTENSIDAD MENSUAL
C34: =SUM(C13+C18) -> #ERROR! | D34: 1 | E34: 0.3 | F34: =H34 -> #ERROR! | G34: 0 | H34: =C34-(C34*E34) -> #ERROR! | I34: =H34/J34 -> #ERROR! | J34: 380 | N34: =SUM(N13+N18) -> #ERROR! | O34: 1 | P34: =(N34-S34)/N34 -> #ERROR! | Q34: =S34 -> #ERROR! | R34: 0 | S34: =H34*0.9 -> #ERROR! | T34: =S34/U34 -> #ERROR! | U34: 380 | Y34: =SUM(Y13+Y18) -> #ERROR! | Z34: 1 | AA34: =(Y34-AD34)/Y34 -> #ERROR! | AB34: =AD34 -> #ERROR! | AC34: 0 | AD34: =H34*0.85 -> #ERROR! | AE34: =AD34/AF34 -> #ERROR! | AF34: 380 | AJ34: =SUM(AJ13+AJ18) -> #ERROR! | AK34: 1 | AL34: =(AJ34-AO34)/AJ34 -> #ERROR! | AM34: =AO34 -> #ERROR! | AN34: 0 | AO34: =H34*0.8 -> #ERROR! | AP34: =AO34/AQ34 -> #ERROR! | AQ34: 380
D35: 12 | E35: 0.05 | F35: =H35/D35 -> #ERROR! | G35: =(H35-F35)/(D35-1) -> #ERROR! | H35: =C34-(C34*E35) -> #ERROR! | I35: =H35/J34 -> #ERROR! | J35: =J34/D35 -> 31.666667 | O35: =+D35 -> 12 | P35: =(N34-S35)/N34 -> #ERROR! | Q35: =F35-(F35*10%) -> #ERROR! | R35: =(S35-Q35)/(O35-1) -> #ERROR! | S35: =H35*0.9 -> #ERROR! | T35: =S35/U34 -> #ERROR! | U35: =U34/O35 -> 31.666667 | Z35: =+D35 -> 12 | AA35: =(Y34-AD35)/Y34 -> #ERROR! | AB35: =F35-(F35*15%) -> #ERROR! | AC35: =(AD35-AB35)/(Z35-1) -> #ERROR! | AD35: =H35*0.85 -> #ERROR! | AE35: =AD35/AF34 -> #ERROR! | AF35: =AF34/Z35 -> 31.666667 | AK35: =+D35 -> 12 | AL35: =(AJ34-AO35)/AJ34 -> #ERROR! | AM35: =F35-(F35*20%) -> #ERROR! | AN35: =(AO35-AM35)/(AK35-1) -> #ERROR! | AO35: =H35*0.8 -> #ERROR! | AP35: =AO35/AQ34 -> #ERROR! | AQ35: =AQ34/AK35 -> 31.666667
C37: Plan 2 Niveles (404 Horas Académicas Niveles B2 y C1) | N37: Plan 2 Niveles (404 Horas Académicas Niveles B2 y C1) | Y37: Plan 2 Niveles (404 Horas Académicas Niveles B2 y C1) | AJ37: Plan 2 Niveles (404 Horas Académicas Niveles B2 y C1)
C38: VALOR FULL PLAN | D38: N° CUOTAS | E38: DESCUENTO | F38: CUOTA INICIAL | G38: VALOR CUOTAS | H38: VALOR TOTAL | I38: VALOR HORA | J38: MAXIMA INTENSIDAD MENSUAL | N38: VALOR FULL PLAN | O38: N° CUOTAS | P38: DESCUENTO | Q38: CUOTA INICIAL | R38: VALOR CUOTAS | S38: VALOR TOTAL | T38: VALOR HORA | U38: MAXIMA INTENSIDAD MENSUAL | Y38: VALOR FULL PLAN | Z38: N° CUOTAS | AA38: DESCUENTO | AB38: CUOTA INICIAL | AC38: VALOR CUOTAS | AD38: VALOR TOTAL | AE38: VALOR HORA | AF38: MAXIMA INTENSIDAD MENSUAL | AJ38: VALOR FULL PLAN | AK38: N° CUOTAS | AL38: DESCUENTO | AM38: CUOTA INICIAL | AN38: VALOR CUOTAS | AO38: VALOR TOTAL | AP38: VALOR HORA | AQ38: MAXIMA INTENSIDAD MENSUAL
C39: =SUM(C18+C18) -> #ERROR! | D39: 1 | E39: 0.3 | F39: =H39 -> #ERROR! | G39: 0 | H39: =C39-(C39*E39) -> #ERROR! | I39: =H39/J39 -> #ERROR! | J39: 404 | N39: =SUM(N18+N18) -> #ERROR! | O39: 1 | P39: =(N39-S39)/N39 -> #ERROR! | Q39: =S39 -> #ERROR! | R39: 0 | S39: =H39*0.9 -> #ERROR! | T39: =S39/U39 -> #ERROR! | U39: 404 | Y39: =SUM(Y18+Y18) -> #ERROR! | Z39: 1 | AA39: =(Y39-AD39)/Y39 -> #ERROR! | AB39: =AD39 -> #ERROR! | AC39: 0 | AD39: =H39*0.85 -> #ERROR! | AE39: =AD39/AF39 -> #ERROR! | AF39: 404 | AJ39: =SUM(AJ18+AJ18) -> #ERROR! | AK39: 1 | AL39: =(AJ39-AO39)/AJ39 -> #ERROR! | AM39: =AO39 -> #ERROR! | AN39: 0 | AO39: =H39*0.8 -> #ERROR! | AP39: =AO39/AQ39 -> #ERROR! | AQ39: 404
D40: 12 | E40: 0.05 | F40: =H40/D40 -> #ERROR! | G40: =(H40-F40)/(D40-1) -> #ERROR! | H40: =C39-(C39*E40) -> #ERROR! | I40: =H40/J39 -> #ERROR! | J40: =J39/D40 -> 33.666667 | O40: =+D40 -> 12 | P40: =(N39-S40)/N39 -> #ERROR! | Q40: =F40-(F40*10%) -> #ERROR! | R40: =(S40-Q40)/(O40-1) -> #ERROR! | S40: =H40*0.9 -> #ERROR! | T40: =S40/U39 -> #ERROR! | U40: =U39/O40 -> 33.666667 | Z40: =+D40 -> 12 | AA40: =(Y39-AD40)/Y39 -> #ERROR! | AB40: =F40-(F40*15%) -> #ERROR! | AC40: =(AD40-AB40)/(Z40-1) -> #ERROR! | AD40: =H40*0.85 -> #ERROR! | AE40: =AD40/AF39 -> #ERROR! | AF40: =AF39/Z40 -> 33.666667 | AK40: =+D40 -> 12 | AL40: =(AJ39-AO40)/AJ39 -> #ERROR! | AM40: =F40-(F40*20%) -> #ERROR! | AN40: =(AO40-AM40)/(AK40-1) -> #ERROR! | AO40: =H40*0.8 -> #ERROR! | AP40: =AO40/AQ39 -> #ERROR! | AQ40: =AQ39/AK40 -> 33.666667
C43: Plan 3 Niveles (502 Horas Académicas Niveles A1, A2 y B1) | N43: Plan 3 Niveles (502 Horas Académicas Niveles A1, A2 y B1) | Y43: Plan 3 Niveles (502 Horas Académicas Niveles A1, A2 y B1) | AJ43: Plan 3 Niveles (502 Horas Académicas Niveles A1, A2 y B1)
C44: VALOR FULL PLAN | D44: N° CUOTAS | E44: DESCUENTO | F44: CUOTA INICIAL | G44: VALOR CUOTAS | H44: VALOR TOTAL | I44: VALOR HORA | J44: MAXIMA INTENSIDAD MENSUAL | N44: VALOR FULL PLAN | O44: N° CUOTAS | P44: DESCUENTO | Q44: CUOTA INICIAL | R44: VALOR CUOTAS | S44: VALOR TOTAL | T44: VALOR HORA | U44: MAXIMA INTENSIDAD MENSUAL | Y44: VALOR FULL PLAN | Z44: N° CUOTAS | AA44: DESCUENTO | AB44: CUOTA INICIAL | AC44: VALOR CUOTAS | AD44: VALOR TOTAL | AE44: VALOR HORA | AF44: MAXIMA INTENSIDAD MENSUAL | AJ44: VALOR FULL PLAN | AK44: N° CUOTAS | AL44: DESCUENTO | AM44: CUOTA INICIAL | AN44: VALOR CUOTAS | AO44: VALOR TOTAL | AP44: VALOR HORA | AQ44: MAXIMA INTENSIDAD MENSUAL
C45: =SUM(C8+C8+C13) -> #ERROR! | D45: 1 | E45: 0.45 | F45: =H45 -> #ERROR! | G45: 0 | H45: =C45-(C45*E45) -> #ERROR! | I45: =H45/J45 -> #ERROR! | J45: 502 | N45: =SUM(N8+N8+N13) -> #ERROR! | O45: 1 | P45: =(N45-S45)/N45 -> #ERROR! | Q45: =S45 -> #ERROR! | R45: 0 | S45: =H45*0.9 -> #ERROR! | T45: =S45/U45 -> #ERROR! | U45: 502 | Y45: =SUM(Y8+Y8+Y13) -> #ERROR! | Z45: 1 | AA45: =(Y45-AD45)/Y45 -> #ERROR! | AB45: =AD45 -> #ERROR! | AC45: 0 | AD45: =H45*0.85 -> #ERROR! | AE45: =AD45/AF45 -> #ERROR! | AF45: 502 | AJ45: =SUM(AJ8+AJ8+AJ13) -> #ERROR! | AK45: 1 | AL45: =(AJ45-AO45)/AJ45 -> #ERROR! | AM45: =AO45 -> #ERROR! | AN45: 0 | AO45: =H45*0.8 -> #ERROR! | AP45: =AO45/AQ45 -> #ERROR! | AQ45: 502
D46: 18 | E46: 0.2 | F46: =H46/D46 -> #ERROR! | G46: =(H46-F46)/(D46-1) -> #ERROR! | H46: =C45-(C45*E46) -> #ERROR! | I46: =H46/J45 -> #ERROR! | J46: =J45/D46 -> 27.888889 | O46: =+D46 -> 18 | P46: =(N45-S46)/N45 -> #ERROR! | Q46: =F46-(F46*10%) -> #ERROR! | R46: =(S46-Q46)/(O46-1) -> #ERROR! | S46: =H46*0.9 -> #ERROR! | T46: =S46/U45 -> #ERROR! | U46: =U45/O46 -> 27.888889 | Z46: =+D46 -> 18 | AA46: =(Y45-AD46)/Y45 -> #ERROR! | AB46: =F46-(F46*15%) -> #ERROR! | AC46: =(AD46-AB46)/(Z46-1) -> #ERROR! | AD46: =H46*0.85 -> #ERROR! | AE46: =AD46/AF45 -> #ERROR! | AF46: =AF45/Z46 -> 27.888889 | AK46: =+D46 -> 18 | AL46: =(AJ45-AO46)/AJ45 -> #ERROR! | AM46: =F46-(F46*20%) -> #ERROR! | AN46: =(AO46-AM46)/(AK46-1) -> #ERROR! | AO46: =H46*0.8 -> #ERROR! | AP46: =AO46/AQ45 -> #ERROR! | AQ46: =AQ45/AK46 -> 27.888889
C48: Plan 3 Niveles (542 Horas Académicas Niveles A2, B1 y B2) | N48: Plan 3 Niveles (542 Horas Académicas Niveles A2, B1 y B2) | Y48: Plan 3 Niveles (542 Horas Académicas Niveles A2, B1 y B2) | AJ48: Plan 3 Niveles (542 Horas Académicas Niveles A2, B1 y B2)
C49: VALOR FULL PLAN | D49: N° CUOTAS | E49: DESCUENTO | F49: CUOTA INICIAL | G49: VALOR CUOTAS | H49: VALOR TOTAL | I49: VALOR HORA | J49: MAXIMA INTENSIDAD MENSUAL | N49: VALOR FULL PLAN | O49: N° CUOTAS | P49: DESCUENTO | Q49: CUOTA INICIAL | R49: VALOR CUOTAS | S49: VALOR TOTAL | T49: VALOR HORA | U49: MAXIMA INTENSIDAD MENSUAL | Y49: VALOR FULL PLAN | Z49: N° CUOTAS | AA49: DESCUENTO | AB49: CUOTA INICIAL | AC49: VALOR CUOTAS | AD49: VALOR TOTAL | AE49: VALOR HORA | AF49: MAXIMA INTENSIDAD MENSUAL | AJ49: VALOR FULL PLAN | AK49: N° CUOTAS | AL49: DESCUENTO | AM49: CUOTA INICIAL | AN49: VALOR CUOTAS | AO49: VALOR TOTAL | AP49: VALOR HORA | AQ49: MAXIMA INTENSIDAD MENSUAL
C50: =SUM(C8+C13+C18) -> #ERROR! | D50: 1 | E50: 0.45 | F50: =H50 -> #ERROR! | G50: 0 | H50: =C50-(C50*E50) -> #ERROR! | I50: =H50/J50 -> #ERROR! | J50: 542 | N50: =SUM(N8+N13+N18) -> #ERROR! | O50: 1 | P50: =(N50-S50)/N50 -> #ERROR! | Q50: =S50 -> #ERROR! | R50: 0 | S50: =H50*0.9 -> #ERROR! | T50: =S50/U50 -> #ERROR! | U50: 542 | Y50: =SUM(Y8+Y13+Y18) -> #ERROR! | Z50: 1 | AA50: =(Y50-AD50)/Y50 -> #ERROR! | AB50: =AD50 -> #ERROR! | AC50: 0 | AD50: =H50*0.85 -> #ERROR! | AE50: =AD50/AF50 -> #ERROR! | AF50: 542 | AJ50: =SUM(AJ8+AJ13+AJ18) -> #ERROR! | AK50: 1 | AL50: =(AJ50-AO50)/AJ50 -> #ERROR! | AM50: =AO50 -> #ERROR! | AN50: 0 | AO50: =H50*0.8 -> #ERROR! | AP50: =AO50/AQ50 -> #ERROR! | AQ50: 542
D51: 18 | E51: 0.2 | F51: =H51/D51 -> #ERROR! | G51: =(H51-F51)/(D51-1) -> #ERROR! | H51: =C50-(C50*E51) -> #ERROR! | I51: =H51/J50 -> #ERROR! | J51: =J50/D51 -> 30.111111 | O51: =+D51 -> 18 | P51: =(N50-S51)/N50 -> #ERROR! | Q51: =F51-(F51*10%) -> #ERROR! | R51: =(S51-Q51)/(O51-1) -> #ERROR! | S51: =H51*0.9 -> #ERROR! | T51: =S51/U50 -> #ERROR! | U51: =U50/O51 -> 30.111111 | Z51: =+D51 -> 18 | AA51: =(Y50-AD51)/Y50 -> #ERROR! | AB51: =F51-(F51*15%) -> #ERROR! | AC51: =(AD51-AB51)/(Z51-1) -> #ERROR! | AD51: =H51*0.85 -> #ERROR! | AE51: =AD51/AF50 -> #ERROR! | AF51: =AF50/Z51 -> 30.111111 | AK51: =+D51 -> 18 | AL51: =(AJ50-AO51)/AJ50 -> #ERROR! | AM51: =F51-(F51*20%) -> #ERROR! | AN51: =(AO51-AM51)/(AK51-1) -> #ERROR! | AO51: =H51*0.8 -> #ERROR! | AP51: =AO51/AQ50 -> #ERROR! | AQ51: =AQ50/AK51 -> 30.111111
C53: Plan 3 Niveles (582 Horas Académicas Niveles B1, B2 y C1) | N53: Plan 3 Niveles (582 Horas Académicas Niveles B1, B2 y C1) | Y53: Plan 3 Niveles (582 Horas Académicas Niveles B1, B2 y C1) | AJ53: Plan 3 Niveles (582 Horas Académicas Niveles B1, B2 y C1)
C54: VALOR FULL PLAN | D54: N° CUOTAS | E54: DESCUENTO | F54: CUOTA INICIAL | G54: VALOR CUOTAS | H54: VALOR TOTAL | I54: VALOR HORA | J54: MAXIMA INTENSIDAD MENSUAL | N54: VALOR FULL PLAN | O54: N° CUOTAS | P54: DESCUENTO | Q54: CUOTA INICIAL | R54: VALOR CUOTAS | S54: VALOR TOTAL | T54: VALOR HORA | U54: MAXIMA INTENSIDAD MENSUAL | Y54: VALOR FULL PLAN | Z54: N° CUOTAS | AA54: DESCUENTO | AB54: CUOTA INICIAL | AC54: VALOR CUOTAS | AD54: VALOR TOTAL | AE54: VALOR HORA | AF54: MAXIMA INTENSIDAD MENSUAL | AJ54: VALOR FULL PLAN | AK54: N° CUOTAS | AL54: DESCUENTO | AM54: CUOTA INICIAL | AN54: VALOR CUOTAS | AO54: VALOR TOTAL | AP54: VALOR HORA | AQ54: MAXIMA INTENSIDAD MENSUAL
...

Sheet Tarifas 2X1
C1: 0.03
C3: TARIFAS INGLES / FRANCES INSTITUTO 2024 PRECIO AL PUBLICO - 2X1 | N3: TARIFAS INGLES / FRANCES SMART ONLINE 2024 PRECIO AL PUBLICO - 2X1
C6: Plan 4 Niveles (704 Horas Académicas Niveles A1, A2, B1 y B2) | N6: Plan 6 Meses Smart OnLine (Basico 1 y Basico 2 o Intermedio 1, 2 y avanzado 1)
C7: VALOR FULL PLAN | D7: N° CUOTAS | E7: DESCUENTO | F7: CUOTA INICIAL | G7: VALOR CUOTAS | H7: VALOR TOTAL | I7: VALOR HORA | J7: MAXIMA INTENSIDAD MENSUAL | N7: VALOR FULL PLAN | O7: N° CUOTAS | P7: DESCUENTO | Q7: CUOTA INICIAL | R7: VALOR CUOTA INICIAL (MINIMA) | S7: VALOR TOTAL
C8: 9555000 | D8: 1 | E8: 0.2988 | F8: =H8 -> 6699966 | G8: 0 | H8: =C8-(C8*E8) -> 6699966 | I8: =H8/J8 -> 9516.9972 | J8: 704 | N8: 2000000 | O8: 1 | P8: 0.25 | Q8: 0 | R8: =S8/O8 -> 1500000 | S8: =N8-(N8*P8) -> 1500000
D9: 22 | E9: 0.0581 | F9: 200000 | G9: =(H9-F9)/(D9-1) -> 419040.69 | H9: =C8-(C8*E9) -> 8999854.5 | I9: =H9/J8 -> 12783.884 | J9: =J8/D9 -> 32 | O9: 6 | P9: 0 | Q9: 150000 | R9: =(S9-Q9)/(O9-1) -> 370000 | S9: =N8-(N8*P9) -> 2000000
C11: Plan 4 Niveles (744 Horas Académicas Niveles A2, B1, B2 y C1) | N11: Plan 9 Meses Smart OnLine (Basico 2, Intermedio 1, 2 y Avanzado 1)
C12: VALOR FULL PLAN | D12: N° CUOTAS | E12: DESCUENTO | F12: CUOTA INICIAL | G12: VALOR CUOTAS | H12: VALOR TOTAL | I12: VALOR HORA | J12: MAXIMA INTENSIDAD MENSUAL | N12: VALOR FULL PLAN | O12: N° CUOTAS | P12: DESCUENTO | Q12: CUOTA INICIAL | R12: VALOR CUOTA INICIAL (MINIMA) | S12: VALOR TOTAL
C13: 10105000 | D13: 1 | E13: 0.337 | F13: =H13 -> 6699615 | G13: 0 | H13: =C13-(C13*E13) -> 6699615 | I13: =H13/J13 -> 9004.8589 | J13: 744 | N13: 3000000 | O13: 1 | P13: 0.3334 | Q13: 0 | R13: =S13/O13 -> 1999800 | S13: =N13-(N13*P13) -> 1999800
D14: 22 | E14: 0.1094 | F14: 200000 | G14: =(H14-F14)/(D14-1) -> 419024.43 | H14: =C13-(C13*E14) -> 8999513 | I14: =H14/J13 -> 12096.12 | J14: =J13/D14 -> 33.818182 | O14: 9 | P14: 0 | Q14: 150000 | R14: =(S14-Q14)/(O14-1) -> 356250 | S14: =N13-(N13*P14) -> 3000000
C16: Plan 5 Niveles (906 Horas Académicas Niveles A1, A2, B1, B2 y C1) | N16: Plan 12 Meses Smart OnLine (Basico 1, 2, Intemerdio 1, 2 y Avanzado 1)
C17: VALOR FULL PLAN | D17: N° CUOTAS | E17: DESCUENTO | F17: CUOTA INICIAL | G17: VALOR CUOTAS | H17: VALOR TOTAL | I17: VALOR HORA | J17: MAXIMA INTENSIDAD MENSUAL | N17: VALOR FULL PLAN | O17: N° CUOTAS | P17: DESCUENTO | Q17: CUOTA INICIAL | R17: VALOR CUOTA INICIAL (MINIMA) | S17: VALOR TOTAL
C18: 12301000 | D18: 1 | E18: 0.431 | F18: =H18 -> 6999269 | G18: 0 | H18: =C18-(C18*E18) -> 6999269 | I18: =H18/J18 -> 7725.4625 | J18: 906 | N18: 4000000 | O18: 1 | P18: 0.25 | Q18: 0 | R18: =S18/O18 -> 3000000 | S18: =N18-(N18*P18) -> 3000000
D19: 24 | E19: 0.244 | F19: 200000 | G19: =(H19-F19)/(D19-1) -> 395632.87 | H19: =C18-(C18*E19) -> 9299556 | I19: =H19/J18 -> 10264.411 | J19: =J18/D19 -> 37.75 | O19: 12 | P19: 0 | Q19: 150000 | R19: =(S19-Q19)/(O19-1) -> 350000 | S19: =N18-(N18*P19) -> 4000000
H33: =150000*6% -> 9000

Sheet Tarifas Rescate
C1: 0.03
C3: TARIFAS INGLES / FRANCES INSTITUTO 2024 PRECIO AL PUBLICO - RESCATE | N3: TARIFAS INGLES / FRANCES SMART ONLINE 2024 PRECIO AL PUBLICO - RESCATE
C6: Plan 4 Niveles (704 Horas Académicas Niveles A1, A2, B1 y B2) | N6: Plan 6 Meses Smart OnLine (Basico 1 y Basico 2 o Intermedio 1, 2 y avanzado 1)
C7: VALOR FULL PLAN | D7: N° CUOTAS | E7: DESCUENTO | F7: CUOTA INICIAL | G7: VALOR CUOTAS | H7: VALOR TOTAL | I7: VALOR HORA | J7: MAXIMA INTENSIDAD MENSUAL | N7: VALOR FULL PLAN | O7: N° CUOTAS | P7: DESCUENTO | Q7: CUOTA INICIAL | R7: VALOR CUOTA INICIAL (MINIMA) | S7: VALOR TOTAL
C8: 9555000 | D8: 1 | E8: 0.6337 | F8: =H8 -> 3499996.5 | G8: 0 | H8: =C8-(C8*E8) -> 3499996.5 | I8: =H8/J8 -> 4971.5859 | J8: 704 | N8: 2000000 | O8: 1 | P8: 0.4 | Q8: 0 | R8: =S8/O8 -> 1200000 | S8: =N8-(N8*P8) -> 1200000
D9: 22 | E9: 0.3721 | F9: 125000 | G9: =(H9-F9)/(D9-1) -> 279742.12 | H9: =C8-(C8*E9) -> 5999584.5 | I9: =H9/J8 -> 8522.1371 | J9: =J8/D9 -> 32 | O9: 6 | P9: 0.25 | Q9: 125000 | R9: =(S9-Q9)/(O9-1) -> 275000 | S9: =N8-(N8*P9) -> 1500000
C11: Plan 4 Niveles (744 Horas Académicas Niveles A2, B1, B2 y C1) | N11: Plan 9 Meses Smart OnLine (Basico 2, Intermedio 1, 2 y Avanzado 1)
C12: VALOR FULL PLAN | D12: N° CUOTAS | E12: DESCUENTO | F12: CUOTA INICIAL | G12: VALOR CUOTAS | H12: VALOR TOTAL | I12: VALOR HORA | J12: MAXIMA INTENSIDAD MENSUAL | N12: VALOR FULL PLAN | O12: N° CUOTAS | P12: DESCUENTO | Q12: CUOTA INICIAL | R12: VALOR CUOTA INICIAL (MINIMA) | S12: VALOR TOTAL
C13: 10105000 | D13: 1 | E13: 0.6537 | F13: =H13 -> 3499361.5 | G13: 0 | H13: =C13-(C13*E13) -> 3499361.5 | I13: =H13/J13 -> 4703.4429 | J13: 744 | N13: 3000000 | O13: 1 | P13: 0.5167 | Q13: 0 | R13: =S13/O13 -> 1449900 | S13: =N13-(N13*P13) -> 1449900
D14: 22 | E14: 0.4063 | F14: 125000 | G14: =(H14-F14)/(D14-1) -> 279730.4 | H14: =C13-(C13*E14) -> 5999338.5 | I14: =H14/J13 -> 8063.627 | J14: =J13/D14 -> 33.818182 | O14: 9 | P14: 0.2334 | Q14: 125000 | R14: =(S14-Q14)/(O14-1) -> 271850 | S14: =N13-(N13*P14) -> 2299800
C16: Plan 5 Niveles (906 Horas Académicas Niveles A1, A2, B1, B2 y C1) | N16: Plan 12 Meses Smart OnLine (Basico 1, 2, Intemerdio 1, 2 y Avanzado 1)
C17: VALOR FULL PLAN | D17: N° CUOTAS | E17: DESCUENTO | F17: CUOTA INICIAL | G17: VALOR CUOTAS | H17: VALOR TOTAL | I17: VALOR HORA | J17: MAXIMA INTENSIDAD MENSUAL | N17: VALOR FULL PLAN | O17: N° CUOTAS | P17: DESCUENTO | Q17: CUOTA INICIAL | R17: VALOR CUOTA INICIAL (MINIMA) | S17: VALOR TOTAL
C18: 12301000 | D18: 1 | E18: 0.6749 | F18: =H18 -> 3999055.1 | G18: 0 | H18: =C18-(C18*E18) -> 3999055.1 | I18: =H18/J18 -> 4413.9681 | J18: 906 | N18: 4000000 | O18: 1 | P18: 0.625 | Q18: 0 | R18: =S18/O18 -> 1500000 | S18: =N18-(N18*P18) -> 1500000
D19: 24 | E19: 0.4716 | F19: 125000 | G19: =(H19-F19)/(D19-1) -> 277167.32 | H19: =C18-(C18*E19) -> 6499848.4 | I19: =H19/J18 -> 7174.2256 | J19: =J18/D19 -> 37.75 | O19: 12 | P19: 0.25 | Q19: 125000 | R19: =(S19-Q19)/(O19-1) -> 261363.64 | S19: =N18-(N18*P19) -> 3000000
H33: =150000*6% -> 9000

Sheet Tarifas Smart Online 2026
C3: TARIFAS INGLES / FRANCES SMART ONLINE 2026 PRECIO AL PUBLICO - CONTADO | L3: TARIFAS INGLES / FRANCES SMART ONLINE 2026 PRECIO AL PUBLICO - FINANCIADO / TU PLAN, TUS CUOTAS | U3: TARIFAS INGLES / FRANCES SMART ONLINE 2026 CONVENIOS
C6: Plan 6 Meses Smart OnLine (Basico 1 y Basico 2 o Intermedio 1, 2 y avanzado 1) | L6: Plan 6 Meses Smart OnLine (Basico 1 y Basico 2 o Intermedio 1, 2 y avanzado 1) | U6: Plan 6 Meses Smart OnLine (Basico 1 y Basico 2 o Intermedio 1, 2 y avanzado 1)
C7: VALOR FULL PLAN | D7: N° CUOTAS | E7: DESCUENTO | F7: VALOR TOTAL | L7: VALOR FULL PLAN | M7: N° CUOTAS | N7: DESCUENTO | O7: CUOTA INICIAL | P7: VALOR CUOTA INICIAL (MINIMA) | Q7: VALOR TOTAL | U7: VALOR FULL PLAN | V7: N° CUOTAS | W7: DESCUENTO | X7: CUOTA INICIAL | Y7: VALOR CUOTA INICIAL (MINIMA) | Z7: VALOR TOTAL
C8: =+'Incre IPC 2025'!E3 -> 2210000 | D8: 1 | E8: 0.55 | F8: =C8-(C8*E8) -> 994500 | L8: =+$C$8 -> 2210000 | M8: 1 | N8: 0.55 | O8: 0 | P8: =Q8/M8 -> 994500 | Q8: =L8-(N8*L8) -> 994500 | U8: =+$C$8 -> 2210000 | V8: 1 | W8: 0.6 | X8: 0 | Y8: =Z8/V8 -> 884000 | Z8: =U8-(W8*U8) -> 884000
M9: 2 | N9: 0.5 | O9: =Q9/M9 -> 552500 | P9: =(Q9-O9)/(M9-1) -> 552500 | Q9: =L8-(N9*L8) -> 1105000 | V9: 2 | W9: 0.55 | X9: =Z9/V9 -> 497250 | Y9: =(Z9-X9)/(V9-1) -> 497250 | Z9: =U8-(W9*U8) -> 994500
C11: Plan 9 Meses Smart OnLine (Basico 2, Intermedio 1, 2 y Avanzado 1) | L11: Plan 9 Meses Smart OnLine (Basico 2, Intermedio 1, 2 y Avanzado 1) | U11: Plan 9 Meses Smart OnLine (Basico 2, Intermedio 1, 2 y Avanzado 1)
C12: VALOR FULL PLAN | D12: N° CUOTAS | E12: DESCUENTO | F12: VALOR TOTAL | L12: VALOR FULL PLAN | M12: N° CUOTAS | N12: DESCUENTO | O12: CUOTA INICIAL | P12: VALOR DEMAS CUOTAS | Q12: VALOR TOTAL | U12: VALOR FULL PLAN | V12: N° CUOTAS | W12: DESCUENTO | X12: CUOTA INICIAL | Y12: VALOR DEMAS CUOTAS | Z12: VALOR TOTAL
C13: =+'Incre IPC 2025'!E4 -> 3314000 | D13: 1 | E13: 0.63 | F13: =C13-(C13*E13) -> 1226180 | L13: =+$C$13 -> 3314000 | M13: =D13 -> 1 | N13: 0.63 | O13: =Q13/M13 -> 1226180 | P13: - | Q13: =L13-(L13*N13) -> 1226180 | U13: =+$C$13 -> 3314000 | V13: =M13 -> 1 | W13: 0.68 | X13: =Z13/V13 -> 1060480 | Y13: - | Z13: =U13-(U13*W13) -> 1060480
M14: 3 | N14: 0.55 | O14: =Q14/M14 -> 497100 | P14: =(Q14-O14)/3 -> 331400 | Q14: =L13-(N14*L13) -> 1491300 | V14: 3 | W14: 0.6 | X14: =Z14/V14 -> 441866.67 | Y14: =(Z14-X14)/2 -> 441866.67 | Z14: =U13-(W14*U13) -> 1325600
M15: 5 | N15: 0.45 | O15: =Q15/M15 -> 364540 | P15: =(Q15-O15)/4 -> 364540 | Q15: =L13-(N15*L13) -> 1822700 | V15: 5 | W15: 0.5 | X15: =Z15/V15 -> 331400 | Y15: =(Z15-X15)/4 -> 331400 | Z15: =U13-(W15*U13) -> 1657000
C17: Plan 12 Meses Smart OnLine (Basico 1, 2, Intemerdio 1, 2 y Avanzado 1) | L17: Plan 12 Meses Smart OnLine (Basico 1, 2, Intemerdio 1, 2 y Avanzado 1) | U17: Plan 12 Meses Smart OnLine (Basico 1, 2, Intemerdio 1, 2 y Avanzado 1)
C18: VALOR FULL PLAN | D18: N° CUOTAS | E18: DESCUENTO | F18: CUOTA INICIAL | G18: VALOR CUOTA INICIAL (MINIMA) | H18: VALOR TOTAL | L18: VALOR FULL PLAN | M18: N° CUOTAS | N18: DESCUENTO | O18: CUOTA INICIAL | P18: VALOR DEMAS CUOTAS | Q18: VALOR TOTAL | U18: VALOR FULL PLAN | V18: N° CUOTAS | W18: DESCUENTO | X18: CUOTA INICIAL | Y18: VALOR DEMAS CUOTAS | Z18: VALOR TOTAL
C19: =+'Incre IPC 2025'!E5 -> 4419000 | D19: 1 | E19: 0.7 | F19: =C19-(C19*E19) -> 1325700 | L19: =+$C$19 -> 4419000 | M19: =D19 -> 1 | N19: 0.7 | O19: 0 | P19: =Q19/M19 -> 1325700 | Q19: =L19-(N19*L19) -> 1325700 | U19: =+$C$19 -> 4419000 | V19: =M19 -> 1 | W19: 0.75 | X19: 0 | Y19: =Z19/V19 -> 1104750 | Z19: =U19-(W19*U19) -> 1104750
M20: 3 | N20: 0.6 | O20: =Q20/M20 -> 589200 | P20: =(Q20-O20)/2 -> 589200 | Q20: =L19-(N20*L19) -> 1767600 | V20: 3 | W20: 0.65 | X20: =Z20/V20 -> 515550 | Y20: =(Z20-X20)/2 -> 515550 | Z20: =U19-(W20*U19) -> 1546650
M21: 5 | N21: 0.5 | O21: =Q21/M21 -> 441900 | P21: =(Q21-O21)/4 -> 441900 | Q21: =L19-(N21*L19) -> 2209500 | V21: 5 | W21: 0.55 | X21: =Z21/V21 -> 397710 | Y21: =(Z21-X21)/4 -> 397710 | Z21: =U19-(W21*U19) -> 1988550
B23: Nota: Para mayor informacion como fechas de inicio, beneficios, caracteristicas, entre otros, acceder desde el correo corporativo al siguiente link: https://docs.google.com/spreadsheets/d/1Q2HqMaMic7_AarZcQqs4PZM9Uu34qmqEp1RHP9H9mXY/edit#gid=1370905412
N27: 3350
N28: =F19/N27 -> 395.73134
C30: SMART ON LINE
C31: Tarifa Publico | F31: Tarifa activa regular abierta | H31: Promocion 2 x 1 + Examen Linguaskills | N31: 660
C32: Tarifa Financiado/Tu plan tus cuotas | F32: Tarifa activa regular abierta | N32: =N27*N31 -> 2211000
C33: Tarifa Convenios | F33: Tarifa activa Convenios si
D35: Campaña Smart Online - Público | E35: 701WP00000jb5h6YAA
D36: Campaña Smart Online - Tu Plan, Tus Cuotas - Público | E36: 701WP00000jcLr8YAE
D38: Campaña Smart Online - Convenios | E38: 701WP00000jcJfnYAE
D39: Campaña Smart Online - Tu Plan, Tus Cuotas - Convenios | E39: 701WP00000jayqLYAQ
D41: Campaña Smart Online - 2x1 - Beca | E41: 701WP00001H1bXtYAJ

Sheet Tarifas Cursos Cortos 2026
B2: CURSOS CORTOS SMART
B5: CURSO | C5: VALOR TOTAL | D5: DURACIÓN (SEMANAS) | E5: HORARIOS DISPONIBLES | F5: MINIMO DE ESTUDIANTES | G5: NIVEL REQUERIDO (SEGÚN TEST SMART) | H5: FECHAS Y MAS INFORMACION
B6: Preparacion Examen MET (2 Habilidades) + Simulacro | C6: ='Incre IPC 2025'!E7 -> 375600 | D6: 2 | E6: 10:00 a.m. o 6:00 P.M. | F6: 5 | G6: B1 | H6: https://docs.google.com/spreadsheets/d/1Q2HqMaMic7_AarZcQqs4PZM9Uu34qmqEp1RHP9H9mXY/edit#gid=1370905412
B7: Preparacion Examen MET (4 Habilidades) + Simulacro | C7: ='Incre IPC 2025'!E8 -> 576700 | D7: 3 | F7: 5
B8: Smart Chef | C8: ='Incre IPC 2025'!E9 -> 576700 | E8: 10:00 a.m. o 6:00 P.M. | F8: 5
B9: Smart Office Suite Skills | C9: ='Incre IPC 2025'!E10 -> 793200 | F9: 5
B10: Smart Bussines English | C10: ='Incre IPC 2025'!E11 -> 865000 | F10: 5

Sheet Tarifas Examenes 2024
B2: PRECIO EXAMENES INTERNACIONALES 2023
B5: EXAMENES MICHIGAN | G5: EXAMENES CAMBRIDGE
B6: EXAMEN | C6: VALOR TOTAL USD | D6: ENFOQUE | E6: NIVEL DE MEDICION | G6: EXAMEN | H6: VALOR TOTAL USD | I6: ENFOQUE | J6: NIVEL DE MEDICION
B7: MYLE - Bronze | C7: 270000 | D7: Niños | E7: Pre A1 | G7: Pre-A1 Starters | H7: 360000 | I7: Niños | J7: Pre A1
B8: MYLE - Silver | C8: 290000 | D8: Niños | E8: A1 | G8: A1 Movers | H8: 370000 | I8: Niños | J8: A1
B9: MYLE - Gold | C9: 305000 | D9: Niños | E9: A2 | G9: A2 Flyers | H9: 390000 | I9: Niños | J9: A2
B10: MET Go! | C10: 245000 | D10: Adolescentes (grados 6 a 9) | E10: Entre A2 a C1 | G10: Linguaskill (2 Habilidades) | H10: 290000 | I10: Jovenes (grado 11) - Adultos | J10: Entre Pre-A1 a C1 superior
B11: MET Go! + Speaking | C11: 300000 | D11: Adolescentes (grados 6 a 9) | E11: Entre A2 a C1 | G11: Linguaskill (4 Habilidades) | H11: 440000 | I11: Jovenes (grado 11) - Adultos | J11: Entre Pre-A1 a C1 superior
B12: MET (2 Habilidades)* | C12: 350000 | D12: Jóvenes (grados 10 y 11) y Adultos | E12: Entre A2 a C1 | G12: CEPT (Placement Test 2 habilidades) | H12: 75000 | I12: Mayores de 12 años | J12: Entre Pre-A1 a C1 superior
B13: MET (4 habilidades)* | C13: 550000 | D13: Jóvenes (grados 10 y 11) y Adultos | E13: Entre A2 a C1 | G13: A2 Key (KET) | H13: 570000 | I13: Adultos | J13: A2 (con certificación extendida: hasta un nivel por encima y por debajo)
B14: ECCE | C14: 650000 | D14: Adultos | E14: B2 | G14: A2 Key for Schools (KETfS) | H14: 570000 | I14: Adolescentes | J14: A2 (con certificación extendida: hasta un nivel por encima y por debajo)
B15: ECPE | C15: 700000 | D15: Adultos | E15: C2 | G15: B1 Preliminary (PET) | H15: 610000 | I15: Adultos | J15: B1 (con certificación extendida: hasta un nivel por encima y por debajo)
G16: B1 Preliminary for Schools (PETfS) | H16: 610000 | I16: Adolescentes | J16: B1 (con certificación extendida: hasta un nivel por encima y por debajo)
G17: B2 First (FCE) | H17: 900000 | I17: Adultos | J17: B2 (con certificación extendida: hasta un nivel por encima y por debajo)
G18: B2 First for Schools (FCE) | H18: 900000 | I18: Adolescentes | J18: B2 (con certificación extendida: hasta un nivel por encima y por debajo)
G19: C1 Advanced | H19: 910000 | I19: Adultos | J19: C1 (con certificación extendida: hasta un nivel por encima y por debajo)
G20: C2 Proficiency | H20: 920000 | I20: Adultos | J20: C2 (con certificación extendida: hasta un nivel por encima)
G21: TKT por módulo | H21: 340000 | I21: Profesionales y Docentes | J21: Competencias académicas (Conocimiento de enseñanza del inglés)
G22: TKT Módulos 1 al 3 | H22: 980000 | I22: Profesionales y Docentes | J22: Competencias académicas (Conocimiento de enseñanza del inglés)

Sheet Tarifas Planes Examanes 2023 UD
A1: TARIFAS EXAMENES (BOGOTA, MEDELLIN O SANTANDER) | H1: TARIFAS EXAMENES REGIONALES (OTRAS CIUDADES)
A3: EXAMENES MICHIGAN 2023 | H3: EXAMENES MICHIGAN 2023 REGIONALES (ORAS CIUDADES)
A4: EXAMEN | B4: VALOR TOTAL PUBLICO | C4: PLAN INICIAL | D4: PLAN BÁSICO | E4: PLAN MEDIO | F4: PLAN PLUS | H4: EXAMEN | I4: PRECIO 2023 USD Regiones
C5: 10 A 39 | D5: 40 a 70 | E5: 71 a 99 | F5: 100 en adelante
A6: MYLE - Bronze* | B6: 48.825 | C6: =B6*0.97 -> 47.36025 | D6: =B6*0.94 -> 45.8955 | E6: =B6*0.91 -> 44.43075 | F6: =B6*0.88 -> 42.966 | H6: MYLE - Bronze | I6: 81.9
A7: MYLE - Silver * | B7: 52.08 | C7: =B7*0.97 -> 50.5176 | D7: =B7*0.94 -> 48.9552 | E7: =B7*0.91 -> 47.3928 | F7: =B7*0.88 -> 45.8304 | H7: MYLE - Silver | I7: 84
A8: MYLE - Gold | B8: 55.335 | C8: =B8*0.97 -> 53.67495 | D8: =B8*0.94 -> 52.0149 | E8: =B8*0.91 -> 50.35485 | F8: =B8*0.88 -> 48.6948 | H8: MYLE - Gold | I8: 87.465
A9: MET Go! | B9: 53.7075 | C9: =B9*0.97 -> 52.096275 | D9: =B9*0.94 -> 50.48505 | E9: =B9*0.91 -> 48.873825 | F9: =B9*0.88 -> 47.2626 | H9: MET Go! | I9: 86.625
A10: MET Go! + Speaking | B10: 64.325 | C10: =B10*0.97 -> 62.39525 | D10: =B10*0.94 -> 60.4655 | E10: =B10*0.91 -> 58.53575 | F10: =B10*0.88 -> 56.606 | H10: MET Go! + Speaking | I10: 97.525
A11: MET (2 Habilidades)* | B11: 75.02 | C11: =B11*0.97 -> 72.7694 | D11: =B11*0.94 -> 70.5188 | E11: =B11*0.91 -> 68.2682 | F11: =B11*0.88 -> 66.0176 | H11: MET 2 Skills | I11: 106.48
A12: MET (4 habilidades)* | B12: 119.7375 | C12: =B12*0.97 -> 116.14538 | D12: =B12*0.94 -> 112.55325 | E12: =B12*0.91 -> 108.96112 | F12: =B12*0.88 -> 105.369 | H12: MET 4 Skills | I12: 146.775
A13: ECCE | B13: 131.75 | C13: =B13*0.97 -> 127.7975 | D13: =B13*0.94 -> 123.845 | E13: =B13*0.91 -> 119.8925 | F13: =B13*0.88 -> 115.94 | H13: ECCE | I13: 170
A14: ECPE | B14: 148.8 | C14: =B14*0.97 -> 144.336 | D14: =B14*0.94 -> 139.872 | E14: =B14*0.91 -> 135.408 | F14: =B14*0.88 -> 130.944 | H14: ECPE | I14: 192
A15: * En los planes: inicial y basico el examen con simulacro tiene un costo adicional de 4 USD para 2 habilidades o 6 USD para 4 habilidades. En el plan medio y plus pregunta con tu asesor que beneficios tienes con los simulacros
A18: EXAMENES CAMBRIDGE | H18: EXAMENES CAMBRIDGE 2023 REGIONALES (OTRAS CIUDADES)
A19: EXAMEN | B19: VALOR TOTAL | C19: PLAN INICIAL | D19: PLAN BÁSICO | E19: PLAN MEDIO | F19: PLAN PLUS | H19: EXAMEN | I19: PRECIO 2023 REGIONAL USD
C20: 10 A 39 | D20: 40 a 70 | E20: 71 a 99 | F20: 100 en adelante
A21: Pre-A1 Starters | B21: 72.5625 | C21: =B21*0.97 -> 70.385625 | D21: =B21*0.94 -> 68.20875 | E21: =B21*0.91 -> 66.031875 | F21: =B21*0.88 -> 63.855 | H21: Pre-A1 Starters | I21: 103.845
A22: A1 Movers | B22: 75.7875 | C22: =B22*0.97 -> 73.513875 | D22: =B22*0.94 -> 71.24025 | E22: =B22*0.91 -> 68.966625 | F22: =B22*0.88 -> 66.693 | H22: A1 Movers | I22: 106.8075
A23: A2 Flyers | B23: 80.325 | C23: =B23*0.97 -> 77.91525 | D23: =B23*0.94 -> 75.5055 | E23: =B23*0.91 -> 73.09575 | F23: =B23*0.88 -> 70.686 | H23: A2 Flyers | I23: 110.925
A24: A2 Key (KET) | B24: 124 | C24: =B24*0.97 -> 120.28 | D24: =B24*0.94 -> 116.56 | E24: =B24*0.91 -> 112.84 | F24: =B24*0.88 -> 109.12 | H24: A2 Key | I24: 124
A25: A2 Key for Schools (KETfS) | B25: 124 | C25: =B25*0.97 -> 120.28 | D25: =B25*0.94 -> 116.56 | E25: =B25*0.91 -> 112.84 | F25: =B25*0.88 -> 109.12 | H25: A2 Key for Schools | I25: 124
A26: B1 Preliminary (PET) | B26: 131 | C26: =B26*0.97 -> 127.07 | D26: =B26*0.94 -> 123.14 | E26: =B26*0.91 -> 119.21 | F26: =B26*0.88 -> 115.28 | H26: B1 Preliminary | I26: 133
A27: B1 Preliminary for Schools (PETfS) | B27: 131 | C27: =B27*0.97 -> 127.07 | D27: =B27*0.94 -> 123.14 | E27: =B27*0.91 -> 119.21 | F27: =B27*0.88 -> 115.28 | H27: B1 Preliminary for Schools | I27: 133
A28: B2 First (FCE) | B28: 195 | C28: =B28*0.97 -> 189.15 | D28: =B28*0.94 -> 183.3 | E28: =B28*0.91 -> 177.45 | F28: =B28*0.88 -> 171.6 | H28: B2 First | I28: 200
A29: B2 First for Schools (FCE) | B29: 195 | C29: =B29*0.97 -> 189.15 | D29: =B29*0.94 -> 183.3 | E29: =B29*0.91 -> 177.45 | F29: =B29*0.88 -> 171.6 | H29: B2 First for Schools | I29: 200
A30: TKT por módulo * | B30: 68.47 | C30: =B30*0.97 -> 66.4159 | D30: =B30*0.94 -> 64.3618 | E30: =B30*0.91 -> 62.3077 | F30: =B30*0.88 -> 60.2536 | H30: TKT por módulo | I30: 99.63
A31: TKT Módulos 1 al 3 * | B31: 190.65 | C31: =B31*0.97 -> 184.9305 | D31: =B31*0.94 -> 179.211 | E31: =B31*0.91 -> 173.4915 | F31: =B31*0.88 -> 167.772 | H31: TKT Módulos 1 al 3 | I31: 246
A32: Nota: En los planes: inicial y basico el examen con simulacro tiene un costo adicional de 4 USD para 2 habilidades o 6 USD para 4 habilidades. En el plan medio y plus pregunta con tu asesor que beneficios tienes con los simulacros * No aplican simulacros
A35: EXAMENES VIRTUALES
A36: EXAMEN | B36: VALOR TOTAL | C36: PLAN BÁSICO | D36: PLAN MEDIO | E36: PLAN PLUS
C37: 20 a 50 | D37: 51 a 150 | E37: 151 o más
A38: Linguaskill (1 Habilidad) | B38: 28.117 | C38: =+B38*0.96 -> 26.99232 | D38: =B38*0.92 -> 25.86764 | E38: =+B38*0.88 -> 24.74296
A39: Linguaskill (2 Habilidades) | B39: 58 | C39: =+B39*0.96 -> 55.68 | D39: =B39*0.92 -> 53.36 | E39: =+B39*0.88 -> 51.04
A40: Linguaskill (4 Habilidades) | B40: 85 | C40: =+B40*0.96 -> 81.6 | D40: =B40*0.92 -> 78.2 | E40: =+B40*0.88 -> 74.8
A42: EXAMENES DE DIAGNOSTICO
A43: EXAMEN | B43: VALOR TOTAL | C43: PLAN INICIAL | D43: PLAN BÁSICO | E43: PLAN MEDIO | F43: PLAN PLUS
C44: 20 A 99 | D44: 100 A 199 | E44: 200 A 499 | F44: 500 O MÁS
A45: CEPT CON RR | B45: 14.725 | C45: =B45*0.94 -> 13.8415 | D45: =B45*0.88 -> 12.958 | E45: =B45*0.82 -> 12.0745 | F45: =+B45*0.76 -> 11.191
A46: CEPT SIN RR | B46: 10.925 | C46: =B46*0.94 -> 10.2695 | D46: =B46*0.88 -> 9.614 | E46: =B46*0.82 -> 8.9585 | F46: =+B46*0.76 -> 8.303
...
